Workbook

Sheet Guide
A1: Micron (MU) Cycle Valuation Model — Guide
A3: Purpose of This Model
A4: Cyclicals like memory cannot be valued on P/E. At the peak, earnings are highest so P/E looks lowest;
A5: at the trough, losses make P/E meaningless. This model offers three alternatives.
A7: ① P/B × ROE | B7: Assumes a sustainable ROE and solves for justified P/B. The standard memory-sector frame.
A8: (2) Normalized earnings | B8: Builds a normalized EPS on mid-cycle margins and applies a multiple.
A9: (3) Probability-weighted scenarios | B9: Assigns probabilities to bull, base and bear cases to produce an expected value.
A11: The Most Useful Way to Read This
A12: Rather than asking what the fair value is, it is more practical to back-solve what the current price already assumes.
A13: On the PB_ROE_Model tab, find the ROE in the sensitivity grid that corresponds to the current price.
A14: Then the only judgment left is whether you believe that ROE.
A16: Cell Colour Legend
A17: Blue text | B17: Hardcoded input or scenario lever
A18: Black text | B18: Formula (calculated automatically - do not edit)
A19: Green text | B19: Reference to another sheet
A20: Yellow fill | B20: [*] Edit here - key assumption input cells
A23: Tab Layout
A24: Assumptions | B24: [*] All inputs live here. Start on this tab.
A25: CurrentData | B25: Micron actuals as of 2026-07-28, with sources noted
A26: HistoricalCycle | B26: Results and valuation from FY2021 to date - context for where the cycle stands
A27: PB_ROE_Model | B27: Justified P/B = (ROE-g)/(COE-g), with an ROE by g sensitivity grid
A28: NormalizedEarnings | B28: Normalized revenue x margin gives normalized EPS, then a target multiple; margin by multiple grid
A29: Scenarios | B29: Probability-weighted expected value across bull, base and bear
A30: Consensus | B30: Full analyst estimates FY2025(A) to FY2029(E) - median, low, high and estimate counts
A31: ConsensusValuation | B31: [*] Forward P/E, P/B and EV/EBITDA by year, plus a consensus achievement (haircut) adjustment
A32: Disclaimer: This file is a template for learning valuation methodology. It is not investment advice, and every assumption must be independently verified by the user.
A33: Created 2026-07-28. Market data sources: Finviz, stockanalysis.com (Fiscal.ai)
A35: Key finding: On the FY2028 consensus BPS of $437.94, forward P/B is 1.91x - below the five-year average of 1.95x.
A36: That assumes consensus is realized in full, including a 70.7% FY2027 net margin. Stress it by lowering the achievement rate on the ConsensusValuation tab.
A39: Added 2026-07-31 — Mix-Based ROE Build-up (tabs 12-15)
A40: MixPath | B40: Wafer allocation to bit share to revenue mix. Anchored on TrendForce actuals with an [*] ASP premium lever.
A41: SegmentMargin | B41: Segment OPM to blended EBIT margin. [*] Cross-check 1 against consensus EBIT margin, deriving the achievement rate.
A42: ROE_Build | B42: Derives ROE via two-factor DuPont. [*] Cross-check 2 against consensus ROE.
A43: TerminalROE | B43: Applies a through-cycle adjustment. RIM_3Stage B10 reads this; manual entry retired.
A45: Note: The information hierarchy has been inverted. Previously terminal ROE was entered by hand and a price fell out. Now ROE is derived from wafer allocation and consensus becomes the thing being tested.
A46: Note: [*] Input cells - MixPath B6:E8 (wafer share, trade ratio, DRAM share) and B11 (premium case); SegmentMargin B6:E8 (segment OPM); TerminalROE B13 (smoothing efficiency).
A48: Added 2026-07-31 (second pass) — ASP Drivers and the Multiple Explanation Layer
A49: SegmentMargin rows 37-52 | B49: (17) ASP Drivers. Retires manual OPM entry and derives it from ASP indices: OPM = 1 - (1 - base OPM) / ASP index.
A50: Scenarios rows 32-63 | B50: (16) Derivation block. Adjusting only three indices - commodity spot ASP, HBM contract ASP and NAND ASP - derives premium, mix, revenue and margin.
A51: PB_Bridge | B51: (18) Splits P/B into three pieces - book value, explicit residual income and terminal. Includes a news routing table.
...

Sheet Tracker
A1: (9) Micron Tracker — What to Watch Before Updating the View
A2: Written 2026-07-29. Margin calls are setting prices right now, so valuation judgment is suspended until the indicators below confirm a regime change.
A4: Stage 1 — Has Forced Liquidation Ended (check daily over the next one to three weeks)
A5: Indicator | B5: How to check | C5: Liquidation ongoing | D5: Signal that liquidation has ended | E5: Log
A6: Circuit breakers and sidecars | B6: KRX disclosures and news | C6: Triggered two days running (Jul 28-29) | D6: No trigger for three sessions or more
A7: Trading value | B7: KRX and Nasdaq daily | C7: Inflated by forced selling | D7: Back to normal levels
A8: Retail net selling | B8: KRX flows by investor type | C8: KRW 1.4tn net selling on Jul 29 | D8: Turns to net buying or neutral
A9: Leveraged ETF assets under management | B9: Single-stock 2x ETF balances | C9: Declining since the late-June peak | D9: Decline stops and flattens
A10: Micron intraday range | B10: ATR(14) at 79.67, or 9.5% of the share price | C10: Above 7% of the share price | D10: Narrows below 4% of the share price
A11: Implied correlation | B11: S&P 500 three-month implied correlation | C11: At multi-decade lows, with AI treated as a dispersion story | D11: A rise means AI has become an aggregate story - warning sign
A13: Stage 2 — Panic or Re-rating (scheduled events)
A14: Date | B14: Event | C14: What to check | D14: Bullish signal | E14: Bearish signal | F14: Log
A15: August 2026 | B15: Capacity calendar of the top three | C15: Timing for Samsung P4/P5, SK hynix M15X and Yongin phase one, and Micron Idaho | D15: Schedules slip or capacity is prioritized to HBM | E15: Start-up pulled forward (SK hynix M15X already confirmed earlier)
A16: Late September to early October 2026 | B16: Micron FY26 Q4 results | C16: (1) direction of ASP to cloud providers (2) FY27 capex guidance (3) progress on HBM contracts | D16: ASP keeps rising with capex discipline | E16: Missing consensus for the same reason as SK hynix would confirm the cycle has turned
A17: October 2026 | B17: SK hynix Q3 results | C17: Whether the Q2 ASP slowdown was one-off | D17: Slowdown reverses and the bonus effect is confirmed as gone | E17: A second consecutive quarter of ASP slowdown
A18: November to December 2026 | B18: HBM4 annual contract price negotiation | C18: HBM has no spot market, so this negotiation is the only price signal | D18: Close to the Goldman forecast of +44-50% | E18: Below the consensus of +34%
A19: 9 December 2026 | B19: Micron CHIPS restriction lifts | C19: (1) buyback size (2) duration (3) whether restrictions remain in years three to five | D19: A specific, large program is announced | E19: No announcement or a small one, repeating the SK hynix pattern
A20: Year-end to early next year | B20: LTA terms disclosed | C20: Level of prepayments, penalties and floor prices | D20: Strong terms would validate the Nomura discount rate argument | E20: Weak terms would kill the case for a lower cost of equity
A22: Stage 3 — Micron-Specific Factors (how it differs from the Korean names)
A23: The drawdown is shallower | B23: Micron is down about 34% from its peak versus KOSPI at -44% and Samsung at -50%. Falling less in the same cycle means more room below.
A24: It has just broken the 200-day line | B24: Broke below the 200-day EMA and the $803.95 support on Jul 29, with no meaningful support beneath. The 200-day simple moving average sits near $506.
A25: Not unrelated to the Korean leveraged ETFs | B25: Peter Kim of KB Securities: forced liquidation is running across Korea, the US, Hong Kong and the UK. A single-stock 2x Micron ETF exists in the US too.
A26: The HBM weighting is different | B26: Micron revenue splits 53% commodity DRAM, 23% HBM and 24% NAND. Direct CXMT competition sits in the 53%.
A27: It has its own catalysts | B27: The CHIPS restriction lifting on Dec 9 and FY26 Q4 results in late September - dates the Korean names do not have.
A28: Volatility is high | B28: ATR(14) of 79.67 equals 9.5% of the share price, with a beta of 2.20. Position size is the risk.
A30: Stage 4 — Update Rules (set in advance)
A31: 1. When the stage 1 indicators show liquidation has ended, resume the valuation discussion. Until then, do not argue about price.
A32: 2. If ASP to cloud providers keeps rising at the late-September results, raise the ConsensusValuation achievement rate to 85-100%.
A33: 3. If Micron also misses consensus for the same reason as SK hynix, cut the achievement rate to 50-60% and reallocate scenario probabilities.
A34: 4. If the Dec 9 buyback announcement is absent or small, treat the case for a lower cost of equity as dead and apply 18% or more rather than 15%.
A35: 5. Under no circumstances put the target multiple and the achievement rate on the optimistic side at the same time. One of the two must use the historical median.
A36: 6. Decide on adding to the position only after stage 1 confirms liquidation has ended. Adding before that is a directional bet, not a valuation judgment.
A38: Note: Record the date checked and the observed value in the yellow log column. When conviction wavers later, the reasoning can be retraced.
A39: Note: This file is not investment advice. It is a tool for organizing the basis of a judgment.
A41: Added 2026-07-30 — New Events and Data to Track
A42: Date | B42: Event | C42: Item to check | D42: Bullish signal | E42: Bearish signal | F42: Log
A43: 2026-08-21 | B43: [*] Apple deadline to reply to the Senate letter | C43: Whether Apple formally commits not to adopt CXMT or YMTC memory, plus disclosures on IP transfer, component qualification status, and any request to prioritize Korean and US suppliers | D43: An Apple commitment not to adopt would give commodity DRAM, 53% of Micron revenue, a political shield | E43: Apple avoiding a firm answer would confirm CXMT qualification is progressing, opening the door globally
A44: Quarterly | B44: Microsoft Azure growth rate | C44: FY26 Q4 at +43%, the highest since early 2022, with roughly +45% guided for the next quarter | D44: Holding above 45% means memory demand is firm | E44: Slowing below 40%
A45: Quarterly | B45: Microsoft underlying capex | C45: Accounting changes - useful life from 15 to 25 years and finance to operating leases - cut the headline from $190B to $175B while actual investment plans are unchanged | D45: Confirming FY2027 capex rises year over year | E45: The shift to operating leases makes this harder to track - reading only the headline leads to the wrong conclusion
A46: Q4 2026 onward | B46: [*] Meta 2027 capex guidance | C46: Not yet provided. Compute is maximized through 2026-27, while chip and server spend from 2028 will depend on actual demand and supply chains. | D46: 2027 guidance issued and raised | E46: Continued reticence on spending from 2028 would weaken the terminal assumptions
...

Sheet Assumptions
A1: Assumptions and Inputs
A3: Item | B3: Value | C3: Unit | D3: Source / Note
A4: Market Data
A5: Current share price | B5: 900 | C5: USD | D5: User-specified, 2026-07-31. Updated from $739 (the Jul 30 low).
A6: Shares outstanding | B6: 1130 | C6: millions of shares | D6: stockanalysis.com, 2026-07-28
A7: Current BVPS (TTM) | B7: 89.22 | C7: USD | D7: stockanalysis.com - equity $100.72B / 1.13B shares
A8: Net cash | B8: 23750 | C8: USD millions | D8: Cash $26.02B less total debt $6.38B
A9: Market capitalization | B9: =B5*B6 -> 1017000 | C9: USD millions | D9: Price x shares outstanding
A10: Current P/B | B10: =B5/B7 -> 10.087424 | C10: x | D10: Price / BVPS (note: actual range 10.09-10.32x)
A12: Cost of Equity
A13: Risk-free rate (Rf) | B13: 0.043 | C13: % | D13: Approximate US 10-year yield - verify and update directly
A14: Beta (5Y) | B14: 2.14 | C14: - | D14: Finviz, 2026-07-28
A15: Equity risk premium (ERP) | B15: 0.05 | C15: % | D15: Typically 4.5-5.5%
A16: Cost of equity (COE) | B16: =B13+B14*B15 -> 0.15 | C16: % | D16: Rf + beta x ERP (CAPM)
A18: Earnings Data
A19: TTM revenue | B19: 90274 | C19: USD millions | D19: stockanalysis.com, TTM(May '26)
A20: TTM net income | B20: 50469 | C20: USD millions | D20: stockanalysis.com, TTM(May '26)
A21: TTM EPS | B21: 44.17 | C21: USD | D21: stockanalysis.com
A22: TTM net margin | B22: =B20/B19 -> 0.55906463 | C22: % | D22: Net income / revenue - an all-time high
A23: TTM ROE | B23: =B20/(B7*B6) -> 0.50059215 | C23: % | D23: Net income / total equity
A24: Next-year EPS consensus | B24: 154.67 | C24: USD | D24: Finviz "EPS next Y", 45-analyst consensus - needs verification
A25: BVPS one year forward | B25: =B7+B24-0.6 -> 243.29 | C25: USD | D25: Current BVPS plus next-year EPS less the $0.60 dividend. Buyback effects ignored.
A26: FY2028 consensus BPS | B26: =Consensus!F24 -> 437.94 | C26: USD | D26: Analyst consensus median (12 estimates)
A27: [*] Model Levers — Edit Here
A28: Sustainable ROE | B28: 0.3 | C28: % | D28: [*] Assumed through-cycle average ROE. Actual five-year range: -12% to 19%.
A29: Perpetual growth rate (g) | B29: 0.05 | C29: % | D29: [*] Must stay below the cost of equity (see B16)
A30: Normalized revenue | B30: 65000 | C30: USD millions | D30: [*] Assumed mid-cycle revenue. FY25 $37.4B, TTM $90.3B.
A31: Normalized net margin | B31: 0.2 | C31: % | D31: [*] Mid-cycle margin. Five-year range: -37.6% to 28.2%.
A32: Normalized target P/E | B32: 12 | C32: x | D32: [*] Multiple applied to normalized earnings. Semiconductors typically 12-18x.
A33: BVPS basis (1 = current, 2 = one year forward, 3 = FY2028) | B33: 3 | C33: - | D33: [*] 1 = current $89, 2 = one year forward, 3 = FY2028 consensus $438
A34: Selected BVPS | B34: =IF(B33=3,B26,IF(B33=2,B25,B7)) -> 437.94 | C34: USD | D34: Set automatically by the choice above
A36: Warning: If COE is less than or equal to g, the justified P/B formula breaks down. Keep g comfortably below COE.
A37: Note: The default is 3 (FY2028 consensus). Comparing against 1 (current BVPS) shows immediately how much the reference date flips the conclusion.

Sheet CurrentData
A1: Current Results and Valuation (as of 2026-07-28)
A3: Item | B3: Value | C3: Unit | D3: Note
A4: Share Price and Market Cap
A5: Share price | B5: 739 | C5: USD | D5: 2026-07-30, -9.94%, volume 67.69m shares
A6: 52-week high | B6: 1255 | C6: USD | D6: Finviz
A7: 52-week low | B7: 103.38 | C7: USD | D7: Finviz
A8: vs 52-week high | B8: =B5/B6-1 -> -0.41115538 | C8: % | D8: Current drawdown - prior cycles ran -50% to -73%
A9: Market capitalization | B9: 946490 | C9: USD millions | D9: Finviz
A10: Valuation Multiples
A11: P/E (TTM) | B11: 18.97 | C11: x | D11: Finviz - beware the illusion of a low P/E at the cycle peak
A12: Forward P/E | B12: 5.42 | C12: x | D12: 838.05 / EPS next Y 154.67
A13: P/B | B13: 9.39 | C13: x | D13: Extreme versus the five-year band of 1.26-2.53x
A14: P/S | B14: 10.48 | C14: x | D14: Five-year band 2.04-4.94x
A15: EV/EBITDA | B15: 13.56 | C15: x | D15: Five-year band 3.62-40.3x
A16: PEG | B16: 0.03 | C16: x | D16: Finviz
A17: Profitability (TTM)
A18: Revenue | B18: 90274 | C18: USD millions | D18: +167% year over year
A19: Net income | B19: 50469 | C19: USD millions | D19: Net margin 55.9% - more than half of revenue drops to net income
A20: Gross margin | B20: 0.7257 | C20: % | D20: Up sharply from 39.8% in FY25
A21: Operating margin | B21: 0.6567 | C21: % | D21: FY25 26.1%
A22: Net margin | B22: 0.5591 | C22: % | D22: [*] All-time high. Prior peak was 28.2% in FY22.
A23: ROE | B23: 0.6664 | C23: % | D23: [*] Five-year average was 7.8%
A24: ROIC | B24: 0.4738 | C24: % | D24: Finviz
A25: Balance Sheet
A26: Debt to equity | B26: 0.06 | C26: x | D26: Effectively debt-free - financial risk is low
A27: Current ratio | B27: 3.42 | C27: x | D27: Current assets / current liabilities - short-term liquidity is very strong
A28: Net cash | B28: 23750 | C28: USD millions | D28: Cash $26.0B less debt $6.4B
A29: Free cash flow | B29: 26172 | C29: USD millions | D29: Operating cash flow $51.4B less capex $25.3B
A30: Consensus
A31: Analyst target price | B31: 1491.95 | C31: USD | D31: 45-analyst average, consensus rating Strong Buy
A32: Upside to target price | B32: =B31/B5-1 -> 1.0188769 | C32: % | D32: Warning: target prices lag the share price (see notes)
A33: Next-year EPS consensus | B33: 154.67 | C33: USD | D33: Finviz 'EPS next Y'
A35: Sources: Finviz (2026-07-28), stockanalysis.com / Fiscal.ai (2026-07-28)

Sheet HistoricalCycle
A1: Historical Cycle — Results and Valuation Trend
A3: Annual results (fiscal year Sep-Aug, USD millions)
A4: Item | B4: FY2021 | C4: FY2022 | D4: FY2023 | E4: FY2024 | F4: FY2025 | G4: TTM 2026 | H4: 5Y average (FY21-25)
A5: Revenue | B5: 27705 | C5: 30758 | D5: 15540 | E5: 25111 | F5: 37378 | G5: 90274 | H5: =AVERAGE(B5:F5) -> 27298.4
A6: Net income | B6: 5861 | C6: 8687 | D6: -5833 | E6: 778 | F6: 8539 | G6: 50469 | H6: =AVERAGE(B6:F6) -> 3606.4
A7: EPS | B7: 5.14 | C7: 7.75 | D7: -5.34 | E7: 0.7 | F7: 7.59 | G7: 44.17 | H7: =AVERAGE(B7:F7) -> 3.168
A8: Gross margin | B8: 0.3762 | C8: 0.4518 | D8: -0.0911 | E8: 0.2235 | F8: 0.3979 | G8: 0.7257 | H8: =AVERAGE(B8:F8) -> 0.27166
A9: Operating margin | B9: 0.2268 | C9: 0.3154 | D9: -0.3697 | E9: 0.0519 | F9: 0.2614 | G9: 0.6563 | H9: =AVERAGE(B9:F9) -> 0.09716
A10: Net margin | B10: 0.2102 | C10: 0.2823 | D10: -0.3755 | E10: 0.0314 | F10: 0.2282 | G10: 0.5589 | H10: =AVERAGE(B10:F10) -> 0.07532
A11: ROE | B11: 0.1405 | C11: 0.1851 | D11: -0.1241 | E11: 0.0177 | F11: 0.1718 | G11: 0.6326 | H11: =AVERAGE(B11:F11) -> 0.0782
A13: Valuation multiples (at each fiscal year end)
A14: Item | B14: FY2021 | C14: FY2022 | D14: FY2023 | E14: FY2024 | F14: FY2025 | G14: TTM 2026 | H14: 5Y average (FY21-25)
A15: Year-end share price | B15: 73.99 | C15: 57.31 | D15: 69.94 | E15: 95.57 | F15: 122 | G15: 838.05 | H15: =AVERAGE(B15:F15) -> 83.762
A16: P/B | B16: 1.88 | C16: 1.26 | D16: 1.74 | E16: 2.35 | F16: 2.53 | G16: 9.39 | H16: =AVERAGE(B16:F16) -> 1.952
A17: P/S | B17: 2.99 | C17: 2.04 | D17: 4.94 | E17: 4.22 | F17: 3.66 | G17: 10.48 | H17: =AVERAGE(B17:F17) -> 3.57
A18: P/E | B18: 14.39 | C18: 7.39 | D18: Loss | E18: 136.53 | F18: 16.07 | G18: 18.97 | H18: =AVERAGE(B18:F18) -> 43.595
A19: EV/EBITDA | B19: 6.52 | C19: 3.62 | D19: 40.34 | E19: 12.32 | F19: 7.83 | G19: 13.56 | H19: =AVERAGE(B19:F19) -> 14.126
A20: Note: The five-year average P/E excludes the loss-making FY2023 (AVERAGE skips text).
A21: P/B stayed within a 1.26-2.53x band across FY21-FY25. The current 9.39x is roughly four to seven times that band.
A22: The TTM net margin of 55.9% is double the prior peak of 28.2% in FY22. Whether that margin holds is the whole valuation question.
A24: Historical maximum drawdowns — reference
A25: Cycle | B25: Drawdown (approx.) | C25: Note
A26: 2000-2002 dot-com and DRAM collapse | B26: -0.9 | C26: Took over ten years to recover
A27: 2007-2008 financial crisis | B27: -0.98 | C27: Roughly thirteen years to recover (the worst on record)
A28: 2014~2016 | B28: -0.73 | C28: Pure cycle with no macro shock
A29: 2018 | B29: -0.57 | C29: Occurred at a trailing P/E of 3-4x, amid a rush of target price upgrades
A30: 2021~2022 | B30: -0.51 | C30: Immediately after a record revenue print
A31: 2024~2025 | B31: -0.6 | C31: Immediately after the sold-out HBM announcement
A32: 2026 to date (ongoing) | B32: -0.33 | C32: Occurred before spot prices had even started falling
A34: Drawdowns are approximate and based on closing prices; figures vary by data source. Sources: Trefis, stockanalysis.com price history.
A35: Results data sources: stockanalysis.com / Fiscal.ai (retrieved 2026-07-28), Micron 10-K

Sheet PB_ROE_Model
A1: (1) P/B x ROE Model — Justified P/B = (ROE - g) / (COE - g)
A3: Inputs (linked automatically from the Assumptions tab)
A4: Current share price | B4: =Assumptions!B5 -> 900
A5: Applied BVPS | B5: =Assumptions!B34 -> 437.94
A6: BVPS basis | B6: =IF(Assumptions!B33=3,"FY2028 consensus BPS",IF(Assumptions!B33=2,"BVPS one year forward","Current BVPS (TTM)")) -> FY2028 consensus BPS
A7: Cost of equity (COE) | B7: =Assumptions!B16 -> 0.15
A8: Assumed sustainable ROE | B8: =Assumptions!B28 -> 0.3
A9: Perpetual growth rate g | B9: =Assumptions!B29 -> 0.05
A11: Base case result
A12: Justified P/B | B12: =IF(B7<=B9,"Error: g >= COE",(B8-B9)/(B7-B9)) -> 2.5
A13: Implied share price | B13: =IF(B7<=B9,"n/a",B12*B5) -> 1094.85
A14: vs current price | B14: =IF(B7<=B9,"n/a",B13/B4-1) -> 0.2165
A16: Sensitivity — implied price (rows: sustainable ROE / columns: perpetual growth g)
A17: ROE \ g | B17: 0.03 | C17: 0.04 | D17: 0.05 | E17: 0.06 | F17: 0.07 | G17: 0.08
A18: 0.1 | B18: =IF($B$7<=B$17,"n/a",($A18-B$17)/($B$7-B$17)*$B$5) -> 255.465 | C18: =IF($B$7<=C$17,"n/a",($A18-C$17)/($B$7-C$17)*$B$5) -> 238.87636 | D18: =IF($B$7<=D$17,"n/a",($A18-D$17)/($B$7-D$17)*$B$5) -> 218.97 | E18: =IF($B$7<=E$17,"n/a",($A18-E$17)/($B$7-E$17)*$B$5) -> 194.64 | F18: =IF($B$7<=F$17,"n/a",($A18-F$17)/($B$7-F$17)*$B$5) -> 164.2275 | G18: =IF($B$7<=G$17,"n/a",($A18-G$17)/($B$7-G$17)*$B$5) -> 125.12571
A19: 0.15 | B19: =IF($B$7<=B$17,"n/a",($A19-B$17)/($B$7-B$17)*$B$5) -> 437.94 | C19: =IF($B$7<=C$17,"n/a",($A19-C$17)/($B$7-C$17)*$B$5) -> 437.94 | D19: =IF($B$7<=D$17,"n/a",($A19-D$17)/($B$7-D$17)*$B$5) -> 437.94 | E19: =IF($B$7<=E$17,"n/a",($A19-E$17)/($B$7-E$17)*$B$5) -> 437.94 | F19: =IF($B$7<=F$17,"n/a",($A19-F$17)/($B$7-F$17)*$B$5) -> 437.94 | G19: =IF($B$7<=G$17,"n/a",($A19-G$17)/($B$7-G$17)*$B$5) -> 437.94
A20: 0.2 | B20: =IF($B$7<=B$17,"n/a",($A20-B$17)/($B$7-B$17)*$B$5) -> 620.415 | C20: =IF($B$7<=C$17,"n/a",($A20-C$17)/($B$7-C$17)*$B$5) -> 637.00364 | D20: =IF($B$7<=D$17,"n/a",($A20-D$17)/($B$7-D$17)*$B$5) -> 656.91 | E20: =IF($B$7<=E$17,"n/a",($A20-E$17)/($B$7-E$17)*$B$5) -> 681.24 | F20: =IF($B$7<=F$17,"n/a",($A20-F$17)/($B$7-F$17)*$B$5) -> 711.6525 | G20: =IF($B$7<=G$17,"n/a",($A20-G$17)/($B$7-G$17)*$B$5) -> 750.75429
A21: 0.25 | B21: =IF($B$7<=B$17,"n/a",($A21-B$17)/($B$7-B$17)*$B$5) -> 802.89 | C21: =IF($B$7<=C$17,"n/a",($A21-C$17)/($B$7-C$17)*$B$5) -> 836.06727 | D21: =IF($B$7<=D$17,"n/a",($A21-D$17)/($B$7-D$17)*$B$5) -> 875.88 | E21: =IF($B$7<=E$17,"n/a",($A21-E$17)/($B$7-E$17)*$B$5) -> 924.54 | F21: =IF($B$7<=F$17,"n/a",($A21-F$17)/($B$7-F$17)*$B$5) -> 985.365 | G21: =IF($B$7<=G$17,"n/a",($A21-G$17)/($B$7-G$17)*$B$5) -> 1063.5686
A22: 0.3 | B22: =IF($B$7<=B$17,"n/a",($A22-B$17)/($B$7-B$17)*$B$5) -> 985.365 | C22: =IF($B$7<=C$17,"n/a",($A22-C$17)/($B$7-C$17)*$B$5) -> 1035.1309 | D22: =IF($B$7<=D$17,"n/a",($A22-D$17)/($B$7-D$17)*$B$5) -> 1094.85 | E22: =IF($B$7<=E$17,"n/a",($A22-E$17)/($B$7-E$17)*$B$5) -> 1167.84 | F22: =IF($B$7<=F$17,"n/a",($A22-F$17)/($B$7-F$17)*$B$5) -> 1259.0775 | G22: =IF($B$7<=G$17,"n/a",($A22-G$17)/($B$7-G$17)*$B$5) -> 1376.3829
A23: 0.4 | B23: =IF($B$7<=B$17,"n/a",($A23-B$17)/($B$7-B$17)*$B$5) -> 1350.315 | C23: =IF($B$7<=C$17,"n/a",($A23-C$17)/($B$7-C$17)*$B$5) -> 1433.2582 | D23: =IF($B$7<=D$17,"n/a",($A23-D$17)/($B$7-D$17)*$B$5) -> 1532.79 | E23: =IF($B$7<=E$17,"n/a",($A23-E$17)/($B$7-E$17)*$B$5) -> 1654.44 | F23: =IF($B$7<=F$17,"n/a",($A23-F$17)/($B$7-F$17)*$B$5) -> 1806.5025 | G23: =IF($B$7<=G$17,"n/a",($A23-G$17)/($B$7-G$17)*$B$5) -> 2002.0114
A24: 0.5 | B24: =IF($B$7<=B$17,"n/a",($A24-B$17)/($B$7-B$17)*$B$5) -> 1715.265 | C24: =IF($B$7<=C$17,"n/a",($A24-C$17)/($B$7-C$17)*$B$5) -> 1831.3855 | D24: =IF($B$7<=D$17,"n/a",($A24-D$17)/($B$7-D$17)*$B$5) -> 1970.73 | E24: =IF($B$7<=E$17,"n/a",($A24-E$17)/($B$7-E$17)*$B$5) -> 2141.04 | F24: =IF($B$7<=F$17,"n/a",($A24-F$17)/($B$7-F$17)*$B$5) -> 2353.9275 | G24: =IF($B$7<=G$17,"n/a",($A24-G$17)/($B$7-G$17)*$B$5) -> 2627.64
A25: 0.6 | B25: =IF($B$7<=B$17,"n/a",($A25-B$17)/($B$7-B$17)*$B$5) -> 2080.215 | C25: =IF($B$7<=C$17,"n/a",($A25-C$17)/($B$7-C$17)*$B$5) -> 2229.5127 | D25: =IF($B$7<=D$17,"n/a",($A25-D$17)/($B$7-D$17)*$B$5) -> 2408.67 | E25: =IF($B$7<=E$17,"n/a",($A25-E$17)/($B$7-E$17)*$B$5) -> 2627.64 | F25: =IF($B$7<=F$17,"n/a",($A25-F$17)/($B$7-F$17)*$B$5) -> 2901.3525 | G25: =IF($B$7<=G$17,"n/a",($A25-G$17)/($B$7-G$17)*$B$5) -> 3253.2686
A26: 0.7 | B26: =IF($B$7<=B$17,"n/a",($A26-B$17)/($B$7-B$17)*$B$5) -> 2445.165 | C26: =IF($B$7<=C$17,"n/a",($A26-C$17)/($B$7-C$17)*$B$5) -> 2627.64 | D26: =IF($B$7<=D$17,"n/a",($A26-D$17)/($B$7-D$17)*$B$5) -> 2846.61 | E26: =IF($B$7<=E$17,"n/a",($A26-E$17)/($B$7-E$17)*$B$5) -> 3114.24 | F26: =IF($B$7<=F$17,"n/a",($A26-F$17)/($B$7-F$17)*$B$5) -> 3448.7775 | G26: =IF($B$7<=G$17,"n/a",($A26-G$17)/($B$7-G$17)*$B$5) -> 3878.8971
A28: Find the cell closest to the current price - that ROE is what the market is assuming.
A30: Back-solve — the sustainable ROE implied by the current price
A31: Formula: ROE = (price / BVPS) x (COE - g) + g
A32: Perpetual growth rate g | B32: Implied ROE | C32: Interpretation
A33: 0.03 | B33: =IF($B$7<=A33,"n/a",($B$4/$B$5)*($B$7-A33)+A33) -> 0.27660912 | C33: Conservative growth assumption
A34: 0.04 | B34: =IF($B$7<=A34,"n/a",($B$4/$B$5)*($B$7-A34)+A34) -> 0.26605836 | C34: Conservative to neutral
A35: 0.05 | B35: =IF($B$7<=A35,"n/a",($B$4/$B$5)*($B$7-A35)+A35) -> 0.2555076 | C35: In line with market growth
A36: 0.06 | B36: =IF($B$7<=A36,"n/a",($B$4/$B$5)*($B$7-A36)+A36) -> 0.24495684 | C36: Neutral to aggressive
A37: 0.07 | B37: =IF($B$7<=A37,"n/a",($B$4/$B$5)*($B$7-A37)+A37) -> 0.23440608 | C37: Aggressive growth assumption
A38: 0.08 | B38: =IF($B$7<=A38,"n/a",($B$4/$B$5)*($B$7-A38)+A38) -> 0.22385532 | C38: Very aggressive assumption
A40: Note: Micron actual ROE over the past five years ranged from -12.4% to 18.5%, averaging 7.8% (see HistoricalCycle).
A41: Note: Using current BVPS is harsh while equity is compounding fast. Set Assumptions B33 to 2 to view the one-year-forward BVPS basis alongside.
A42: Note: Toggle Assumptions B33 between 1 and 3. On the same ROE assumption, the implied price shifts by nearly fivefold depending on the BPS basis.
A43: Note: Consensus FY2028 ROE median is 44.9% with a low of 24.3%; FY2029 median is 29.6% (Consensus rows 27-29).

Sheet NormalizedEarnings
A1: (2) Normalized Earnings Model — Fair Value on Mid-Cycle Margins
A3: Why This Method Is Needed
A4: The current 55.9% net margin is an all-time high and double the prior peak of 28.2% in FY22. Applying a multiple to EPS built on
A5: that margin capitalizes peak-cycle earnings in perpetuity. Normalizing corrects for this.
A7: Calculation (inputs linked from the Assumptions tab)
A8: Normalized revenue (USD millions) | B8: =Assumptions!B30 -> 65000 | C8: [*] Edit on Assumptions B30
A9: Normalized net margin | B9: =Assumptions!B31 -> 0.2 | C9: [*] Edit on Assumptions B31
A10: Normalized net income | B10: =B8*B9 -> 13000 | C10: Revenue x margin
A11: Shares outstanding (millions) | B11: =Assumptions!B6 -> 1130
A12: Normalized EPS | B12: =B10/B11 -> 11.504425 | C12: Net income / shares outstanding
A13: Normalized target P/E | B13: =Assumptions!B32 -> 12 | C13: [*] Edit on Assumptions B32
A14: Business value per share | B14: =B12*B13 -> 138.0531 | C14: Normalized EPS x target multiple
A15: Plus net cash per share | B15: =Assumptions!B8/Assumptions!B6 -> 21.017699 | C15: Net cash $23.75B across 1.13B shares (value of the debt-free position)
A16: Implied share price (total) | B16: =B14+B15 -> 159.0708 | C16: Business value plus net cash
A17: Current share price | B17: =Assumptions!B5 -> 900 | C17: Finviz 2026-07-28
A18: vs current price | B18: =B16/B17-1 -> -0.82325467
A20: Reference: historical range (basis for the normalization assumptions)
A21: Item | B21: FY2021 | C21: FY2022 | D21: FY2023 | E21: FY2024 | F21: FY2025 | G21: TTM 2026 | H21: FY21-25 average
A22: Revenue (USD millions) | B22: =HistoricalCycle!B5 -> 27705 | C22: =HistoricalCycle!C5 -> 30758 | D22: =HistoricalCycle!D5 -> 15540 | E22: =HistoricalCycle!E5 -> 25111 | F22: =HistoricalCycle!F5 -> 37378 | G22: =HistoricalCycle!G5 -> 90274 | H22: =HistoricalCycle!H5 -> 27298.4
A23: Net margin | B23: =HistoricalCycle!B10 -> 0.2102 | C23: =HistoricalCycle!C10 -> 0.2823 | D23: =HistoricalCycle!D10 -> -0.3755 | E23: =HistoricalCycle!E10 -> 0.0314 | F23: =HistoricalCycle!F10 -> 0.2282 | G23: =HistoricalCycle!G10 -> 0.5589 | H23: =HistoricalCycle!H10 -> 0.07532
A24: Note: The FY21-25 average net margin is about 7.5%, including the large FY23 loss. Excluding loss years it is roughly 18.8%.
A26: Sensitivity — implied price (rows: normalized net margin / columns: target P/E, net cash per share included)
A27: Net margin \ P/E | B27: 8 | C27: 10 | D27: 12 | E27: 15 | F27: 18 | G27: 20 | H27: 25
A28: 0.05 | B28: =$B$8*$A28/$B$11*B$27+$B$15 -> 44.026549 | C28: =$B$8*$A28/$B$11*C$27+$B$15 -> 49.778761 | D28: =$B$8*$A28/$B$11*D$27+$B$15 -> 55.530973 | E28: =$B$8*$A28/$B$11*E$27+$B$15 -> 64.159292 | F28: =$B$8*$A28/$B$11*F$27+$B$15 -> 72.787611 | G28: =$B$8*$A28/$B$11*G$27+$B$15 -> 78.539823 | H28: =$B$8*$A28/$B$11*H$27+$B$15 -> 92.920354
A29: 0.1 | B29: =$B$8*$A29/$B$11*B$27+$B$15 -> 67.035398 | C29: =$B$8*$A29/$B$11*C$27+$B$15 -> 78.539823 | D29: =$B$8*$A29/$B$11*D$27+$B$15 -> 90.044248 | E29: =$B$8*$A29/$B$11*E$27+$B$15 -> 107.30088 | F29: =$B$8*$A29/$B$11*F$27+$B$15 -> 124.55752 | G29: =$B$8*$A29/$B$11*G$27+$B$15 -> 136.06195 | H29: =$B$8*$A29/$B$11*H$27+$B$15 -> 164.82301
A30: 0.15 | B30: =$B$8*$A30/$B$11*B$27+$B$15 -> 90.044248 | C30: =$B$8*$A30/$B$11*C$27+$B$15 -> 107.30088 | D30: =$B$8*$A30/$B$11*D$27+$B$15 -> 124.55752 | E30: =$B$8*$A30/$B$11*E$27+$B$15 -> 150.44248 | F30: =$B$8*$A30/$B$11*F$27+$B$15 -> 176.32743 | G30: =$B$8*$A30/$B$11*G$27+$B$15 -> 193.58407 | H30: =$B$8*$A30/$B$11*H$27+$B$15 -> 236.72566
A31: 0.2 | B31: =$B$8*$A31/$B$11*B$27+$B$15 -> 113.0531 | C31: =$B$8*$A31/$B$11*C$27+$B$15 -> 136.06195 | D31: =$B$8*$A31/$B$11*D$27+$B$15 -> 159.0708 | E31: =$B$8*$A31/$B$11*E$27+$B$15 -> 193.58407 | F31: =$B$8*$A31/$B$11*F$27+$B$15 -> 228.09735 | G31: =$B$8*$A31/$B$11*G$27+$B$15 -> 251.10619 | H31: =$B$8*$A31/$B$11*H$27+$B$15 -> 308.62832
A32: 0.25 | B32: =$B$8*$A32/$B$11*B$27+$B$15 -> 136.06195 | C32: =$B$8*$A32/$B$11*C$27+$B$15 -> 164.82301 | D32: =$B$8*$A32/$B$11*D$27+$B$15 -> 193.58407 | E32: =$B$8*$A32/$B$11*E$27+$B$15 -> 236.72566 | F32: =$B$8*$A32/$B$11*F$27+$B$15 -> 279.86726 | G32: =$B$8*$A32/$B$11*G$27+$B$15 -> 308.62832 | H32: =$B$8*$A32/$B$11*H$27+$B$15 -> 380.53097
A33: 0.3 | B33: =$B$8*$A33/$B$11*B$27+$B$15 -> 159.0708 | C33: =$B$8*$A33/$B$11*C$27+$B$15 -> 193.58407 | D33: =$B$8*$A33/$B$11*D$27+$B$15 -> 228.09735 | E33: =$B$8*$A33/$B$11*E$27+$B$15 -> 279.86726 | F33: =$B$8*$A33/$B$11*F$27+$B$15 -> 331.63717 | G33: =$B$8*$A33/$B$11*G$27+$B$15 -> 366.15044 | H33: =$B$8*$A33/$B$11*H$27+$B$15 -> 452.43363
A34: 0.4 | B34: =$B$8*$A34/$B$11*B$27+$B$15 -> 205.0885 | C34: =$B$8*$A34/$B$11*C$27+$B$15 -> 251.10619 | D34: =$B$8*$A34/$B$11*D$27+$B$15 -> 297.12389 | E34: =$B$8*$A34/$B$11*E$27+$B$15 -> 366.15044 | F34: =$B$8*$A34/$B$11*F$27+$B$15 -> 435.17699 | G34: =$B$8*$A34/$B$11*G$27+$B$15 -> 481.19469 | H34: =$B$8*$A34/$B$11*H$27+$B$15 -> 596.23894
A35: 0.5 | B35: =$B$8*$A35/$B$11*B$27+$B$15 -> 251.10619 | C35: =$B$8*$A35/$B$11*C$27+$B$15 -> 308.62832 | D35: =$B$8*$A35/$B$11*D$27+$B$15 -> 366.15044 | E35: =$B$8*$A35/$B$11*E$27+$B$15 -> 452.43363 | F35: =$B$8*$A35/$B$11*F$27+$B$15 -> 538.71681 | G35: =$B$8*$A35/$B$11*G$27+$B$15 -> 596.23894 | H35: =$B$8*$A35/$B$11*H$27+$B$15 -> 740.04425
A37: Note: The grid above holds normalized revenue (Assumptions B30) fixed. Changing the revenue assumption shifts the entire table.
A38: Note: This method tends to produce very low values. Understand the two reasons before using it:
A39: (1) It ignores the cash the company earns on the way to normalization - the Scenarios tab corrects for this.
A40: (2) If HBM has structurally raised margins, the normalized margin itself should be set above the historical level.

Sheet Scenarios
A1: (3) Probability-Weighted Scenario Value (valued two to three years forward)
A3: Scenario definitions — edit the blue cells freely (values below are illustrative defaults)
A4: Scenarios | B4: Core logic | C4: Normalized revenue ($m) | D4: Net margin | E4: EPS | F4: Target P/E | G4: Business value | H4: Cumulative FCF (per share) | I4: Implied price | J4: Probability
A5: Bull | B5: Spot +15%, HBM contract price +35% — repricing succeeds | C5: =F54 -> 339435.2 | D5: =J54 -> 0.64049288 | E5: =C5*D5/Assumptions!$B$6 -> 192.39454 | F5: 10 | G5: =E5*F5 -> 1923.9454 | H5: 250 | I5: =G5+H5 -> 2173.9454 | J5: 0.25
A6: Base | B6: TrendForce and consensus baseline (spot and contract both at 100%) | C6: =F55 -> 285117 | D6: =J55 -> 0.5996267 | E6: =C6*D6/Assumptions!$B$6 -> 151.29537 | F6: 9 | G6: =E6*F6 -> 1361.6583 | H6: 180 | I6: =G6+H6 -> 1541.6583 | J6: 0.5
A7: Bear | B7: Spot -65%, HBM contract price -40% — the 2026 surge unwinds | C7: =F56 -> 136325.83 | D7: =J56 -> 0.32090264 | E7: =C7*D7/Assumptions!$B$6 -> 38.714442 | F7: 8 | G7: =E7*F7 -> 309.71553 | H7: 90 | I7: =G7+H7 -> 399.71553 | J7: 0.25
A8: Probability total | J8: =SUM(J5:J7) -> 1
A9: =IF(ABS(J8-1)>0.001,"Warning: probabilities do not sum to 100% - adjust J5:J7","OK - probabilities sum to 100%") -> OK - probabilities sum to 100%
A10: Note: Cumulative FCF per share is the free cash the company accumulates before the valuation date. Cyclicals earn substantial cash on the way to normalization, so it must be added. Current FCF runs about $23 per share per year.
A12: Results
A13: Probability-weighted expected price | B13: =SUMPRODUCT(I5:I7,J5:J7)/J8 -> 1414.2444 | C13: Sum of each scenario price times its probability
A14: Current share price | B14: =Assumptions!B5 -> 900 | C14: Finviz 2026-07-28
A15: Expected return | B15: =B13/B14-1 -> 0.57138266 | C15: Expected price / current price - 1
A16: Upside in the bull case | B16: =I5/B14-1 -> 1.4154949
A17: Downside in the bear case | B17: =I7/B14-1 -> -0.55587163
A18: Payoff asymmetry | B18: =IFERROR(ABS(I5/B14-1)/ABS(I7/B14-1),"n/a") -> 2.546442 | C18: Above 1 means upside exceeds downside
A19: Probability implied by the current price (on the bull case) | B19: =IFERROR((B14-I7)/(I5-I7),"n/a") -> 0.28197275 | C19: The current price requires assigning roughly this probability to the bull case (a two-state bull/bear approximation)
A21: The Variables That Actually Decide the Scenario
A22: 1. Capacity calendar of the top three | B22: Timing of Samsung P4/P5 and SK hynix M15X coming online - the point where supply growth overtakes demand growth of roughly 36%
A23: 2. HBM4 annual contract price | B23: The negotiation outcome around year-end. HBM has no spot market, so this is the only price signal.
A24: 3. Customer inventory days | B24: When hyperscalers stop pre-buying. This leads the capex headlines.
A26: Note: The revenue, margin, multiple, cumulative FCF and probability figures above are illustrative defaults. Replace them with your own judgment.
A27: Note: This file is not investment advice. It is a template for learning valuation methodology.
A28: Note: Defaults were rescaled to the consensus level (bull = FY2028 consensus median, base = consensus low, bear = oversupply).
A29: Note: Cumulative FCF approximates three years of per-share cash flow across FY2026-2028 (consensus CFPS of $74, $160 and $201, less capex).
A32: (16) Derivation Block — Spot DRAM Price Drives the Scenarios (rewritten 2026-07-31)
A33: The driver is the commodity DRAM spot ASP. HBM is contracted and moves separately and more slowly. The ASP premium, revenue, mix and margins are all derived here rather than entered by hand.
A35: Baseline (TrendForce and consensus = 100%)
A36: FY2028 HBM bit share | B36: =MixPath!D19 -> 0.15217391 | C36: Physical layer, independent of price
A37: FY2028 DRAM revenue share | B37: =MixPath!D8 -> 0.8
A38: Base ASP premium (FY2026 actual) | B38: =MixPath!B15 -> 4.39 | C38: 4.39x, back-solved from Micron actuals
A39: Base commodity DRAM OPM | B39: =SegmentMargin!D6 -> 0.77777778 | C39: ⑬ FY2028
A40: Base HBM OPM | B40: =SegmentMargin!D7 -> 0.75 | C40: ⑬ FY2028
A41: Base NAND OPM | B41: =SegmentMargin!D8 -> 0.44444444 | C41: ⑬ FY2028
A42: Consensus FY2028 revenue ($m) | B42: =Consensus!F6 -> 285117 | C42: Embeds the TrendForce spot price assumption
A43: Effective tax rate | B43: =ROE_Build!B5 -> 0.145
A44: Shares outstanding (millions) | B44: =Assumptions!B6 -> 1130
A46: [*] Scenario definitions — adjust only the price indices
A47: Basis | B47: [*] Commodity spot ASP index | C47: [*] HBM contract ASP index | D47: [*] NAND ASP index | E47: Character
A48: Bull | B48: 1.15 | C48: 1.35 | D48: 1 | E48: Spot holds firm and HBM4 contract repricing succeeds (Goldman +44-50%)
...

Sheet Consensus
A1: Analyst Consensus Estimates (FY2025 actual to FY2029E)
A2: Fiscal year runs Sep-Aug. Units in USD millions (per-share figures in USD). Source: consensus screen supplied by the user, retrieved 2026-07-28.
A4: Income Statement — Median Estimates
A5: Item | B5: Basis | C5: FY2025(A) | D5: FY2026(E) | E5: FY2027(E) | F5: FY2028(E) | G5: FY2029(E) | H5: Note
A6: Revenue | B6: Median | C6: 37378 | D6: 129459 | E6: 246699 | F6: 285117 | G6: 289549 | H6: Surges through FY27, then flattens in FY28-29
B7: Estimate count | D7: 45 | E7: 46 | F7: 31 | G7: 5 | H7: Only five estimates for FY29 - low confidence
A8: Gross profit | B8: Median | C8: 15288 | D8: 103973 | E8: 215170 | F8: 230379 | G8: 180733
A9: Gross margin | B9: % | C9: 0.409 | D9: 0.805 | E9: 0.8607 | F9: 0.803 | G9: 0.672 | H9: An 86% gross margin in FY27 would be unprecedented in semiconductors
A10: EBIT | B10: Median | C10: 10846 | D10: 98022 | E10: 205831 | F10: 223740 | G10: 188829
A11: EBIT margin | B11: % | C11: 0.2902 | D11: 0.7589 | E11: 0.8233 | F11: 0.7799 | G11: 0.7021
A12: EBITDA | B12: Median | C12: 19198 | D12: 107951 | E12: 222099 | F12: 246363 | G12: 213073
A13: EBITDA margin | B13: % | C13: 0.5136 | D13: 0.8358 | E13: 0.8884 | F13: 0.8587 | G13: 0.7922
A14: Pretax income | B14: Median | C14: 10785 | D14: 98737 | E14: 208426 | F14: 219435 | G14: 220433
A15: Net income | B15: Median | C15: 9470 | D15: 84014 | E15: 176699 | F15: 189388 | G15: 160492
A16: Net margin | B16: % | C16: 0.2534 | D16: 0.6505 | E16: 0.7068 | F16: 0.6601 | G16: 0.5967 | H16: [*] A 70.7% net margin in FY27 is an extreme assumption
B17: Estimate count | D17: 39 | E17: 39 | F17: 26 | G17: 3
A18: EPS (adjusted) | B18: Median | C18: 8.29 | D18: 73.13 | E18: 154.66 | F18: 170.38 | G18: 141.59 | H18: [*] The core valuation input
B19: Estimate count | D19: 47 | E19: 47 | F19: 31 | G19: 4
A20: GAAP EPS | B20: Median | C20: 7.59 | D20: 72.27 | E20: 153.65 | F20: 176.84 | G20: 101.54
A22: Per-Share and Balance Sheet — Median Estimates
A23: Item | B23: Basis | C23: FY2025(A) | D23: FY2026(E) | E23: FY2027(E) | F23: FY2028(E) | G23: FY2029(E) | H23: Note
A24: BPS (book value per share) | B24: Median | C24: 48.4 | D24: 118.72 | E24: 259.02 | F24: 437.94 | G24: 643.7 | H24: [*] The denominator in every P/B calculation
B25: Estimate count | C25: - | D25: 16 | E25: 16 | F25: 12 | G25: 2 | H25: FY28 has 12 estimates
A26: NAVPS (net asset value per share) | B26: Median | C26: 48.4 | D26: 122.16 | E26: 291.95 | F26: 442.77 | G26: - | H26: Only one estimate - reference only
A27: ROE | B27: Median | C27: 0.1907 | D27: 0.844 | E27: 0.7384 | F27: 0.4486 | G27: 0.296 | H27: [*] Consensus itself already assumes normalization
A28: ROE low | B28: % | C28: - | D28: 0.424 | E28: 0.366 | F28: 0.243 | G28: 0.148 | H28: Approximates the bear case
A29: ROE high | B29: % | C29: - | D29: 0.9098 | E29: 1.1097 | F29: 0.8632 | G29: 0.701
A30: ROA | B30: Median | C30: 0.1244 | D30: 0.6521 | E30: 0.6883 | F30: 0.4467 | G30: 0.3865
A31: Net debt | B31: Median | C31: 4270 | D31: -40902 | E31: -143648 | F31: -265525 | G31: -318921 | H31: Negative means net cash. FY28 net cash of $266B.
A32: CAPEX | B32: Median | C32: 15857 | D32: 27701 | E32: 47089 | F32: 48000 | G32: 55461 | H32: Large capacity additions from FY27 - the seed of the next oversupply
A33: Cash flow per share (CFPS) | B33: Median | C33: 15.33 | D33: 74.49 | E33: 160.05 | F33: 201.29 | G33: 208.67
A35: Estimate Dispersion — How Much Confidence Does Consensus Deserve
A36: Item | B36: FY2026(E) | C36: FY2027(E) | D36: FY2028(E) | E36: FY2029(E) | F36: Note
A37: Revenue low | B37: 113900 | C37: 203043 | D37: 208018 | E37: 214242
A38: Revenue median | B38: 129459 | C38: 246699 | D38: 285117 | E38: 289549
A39: Revenue high | B39: 138764 | C39: 342515 | D39: 405709 | E39: 303053
A40: EPS low | B40: 60.9 | C40: 119.4 | D40: 136 | E40: 101.94
A41: EPS median | B41: 73.13 | C41: 154.66 | D41: 170.38 | E41: 141.59
A42: EPS high | B42: 80.16 | C42: 221.27 | D42: 254.85 | E42: 185.86
A43: BPS low | B43: 99.71 | C43: 197.12 | D43: 311.26 | E43: 643.7
...

Sheet ConsensusValuation
A1: (4) Consensus-Based Valuation by Year (through FY2028)
A3: Reference Data
A4: Current share price | B4: =Assumptions!B5 -> 900 | C4: Finviz 2026-07-28
A5: Shares outstanding (millions) | B5: =Assumptions!B6 -> 1130
A6: Market capitalization (USD millions) | B6: =B4*B5 -> 1017000 | C6: Price x shares outstanding
A8: Multiples from applying the current price to each year of consensus
A9: Item | B9: FY2025(A) | C9: FY2026(E) | D9: FY2027(E) | E9: FY2028(E) | F9: Note
A10: EPS (consensus median) | B10: =Consensus!C18 -> 8.29 | C10: =Consensus!D18 -> 73.13 | D10: =Consensus!E18 -> 154.66 | E10: =Consensus!F18 -> 170.38
A11: BPS (consensus median) | B11: =Consensus!C24 -> 48.4 | C11: =Consensus!D24 -> 118.72 | D11: =Consensus!E24 -> 259.02 | E11: =Consensus!F24 -> 437.94
A12: EBITDA | B12: =Consensus!C12 -> 19198 | C12: =Consensus!D12 -> 107951 | D12: =Consensus!E12 -> 222099 | E12: =Consensus!F12 -> 246363
A13: Net debt (negative = net cash) | B13: =Consensus!C31 -> 4270 | C13: =Consensus!D31 -> -40902 | D13: =Consensus!E31 -> -143648 | E13: =Consensus!F31 -> -265525
A14: → P/E | B14: =IFERROR($B$4/B10,"n/a") -> 108.56454 | C14: =IFERROR($B$4/C10,"n/a") -> 12.306851 | D14: =IFERROR($B$4/D10,"n/a") -> 5.8192163 | E14: =IFERROR($B$4/E10,"n/a") -> 5.2823101 | F14: Current price / EPS for each year
A15: → P/B | B15: =IFERROR($B$4/B11,"n/a") -> 18.595041 | C15: =IFERROR($B$4/C11,"n/a") -> 7.5808625 | D15: =IFERROR($B$4/D11,"n/a") -> 3.4746352 | E15: =IFERROR($B$4/E11,"n/a") -> 2.055076 | F15: Current price / BPS for each year [*] the forward P/B in question
A16: → EV/EBITDA | B16: =IFERROR(($B$6+B13)/B12,"n/a") -> 53.196687 | C16: =IFERROR(($B$6+C13)/C12,"n/a") -> 9.0420469 | D16: =IFERROR(($B$6+D13)/D12,"n/a") -> 3.9322644 | E16: =IFERROR(($B$6+E13)/E12,"n/a") -> 3.0502754 | F16: EV = market cap plus net debt (net cash is deducted)
A18: Taken at face value, consensus puts FY2028 P/B near 1.9x and P/E near 4.9x, which looks cheap. The section below tests that premise.
A20: [*] Consensus Achievement (Haircut) Adjustment — The Critical Input
A21: Memory consensus uses current DRAM prices as an input, so it structurally lags the cycle.
A22: Lower the achievement rate below and see how far the valuation holds. 100% means consensus in full.
A24: [*] Consensus achievement rate | B24: =AVERAGE(SegmentMargin!B21:D21) -> 0.87716314 | C24: Linked to the average SegmentMargin achievement rate for FY2026-28, replacing the prior arbitrary 60%. Overwrite with a number to set it manually.
A25: FY2025 actual BPS | B25: =Consensus!C24 -> 48.4 | C25: Starting point - a confirmed actual
A26: Cumulative EPS FY26-28 (consensus) | B26: =Consensus!D18+Consensus!E18+Consensus!F18 -> 398.17 | C26: Sum of earnings per share over three years
A27: Adjusted FY2028 EPS | B27: =Consensus!F18*B24 -> 149.45106 | C27: Consensus EPS x achievement rate
A28: Adjusted FY2028 BPS | B28: =B25+B26*B24 -> 397.66005 | C28: FY25 BPS plus cumulative EPS x achievement rate (dividends ignored)
A29: Adjusted P/E | B29: =IFERROR($B$4/B27,"n/a") -> 6.0220384
A30: Adjusted P/B | B30: =IFERROR($B$4/B28,"n/a") -> 2.2632397
A31: Note: The achievement rate comes from the EBIT margin ratio. Since revenue is held at consensus, it approximates the earnings ratio. It applies to cumulative EPS in B26, so the FY2026-28 average is used.
A32: Applying Target Multiples — Implied Price
A33: Target P/E | B33: 10 | C33: [*] Normal multiple for a cyclical. Adjust within an 8-15x range.
A34: Implied price, P/E method | B34: =B27*B33 -> 1494.5106 | C34: Adjusted FY28 EPS x target P/E
A35: Target P/B | B35: 2 | C35: [*] The five-year P/B band is 1.26-2.53x, averaging 1.95x
A36: Implied price, P/B method | B36: =B28*B35 -> 795.32009 | C36: Adjusted FY28 BPS x target P/B
A37: Average of the two methods | B37: =AVERAGE(B34,B36) -> 1144.9153
A38: Current share price | B38: =B4 -> 900
A39: vs current price | B39: =B37/B38-1 -> 0.27212814
A41: Sensitivity — implied price (rows: consensus achievement rate / columns: target P/B on FY2028 BPS)
A42: Achievement rate \ Target P/B | B42: 1 | C42: 1.5 | D42: 2 | E42: 2.5 | F42: 3 | G42: 3.5 | H42: 4
A43: 0.3 | B43: =($B$25+$B$26*$A43)*B$42 -> 167.851 | C43: =($B$25+$B$26*$A43)*C$42 -> 251.7765 | D43: =($B$25+$B$26*$A43)*D$42 -> 335.702 | E43: =($B$25+$B$26*$A43)*E$42 -> 419.6275 | F43: =($B$25+$B$26*$A43)*F$42 -> 503.553 | G43: =($B$25+$B$26*$A43)*G$42 -> 587.4785 | H43: =($B$25+$B$26*$A43)*H$42 -> 671.404
A44: 0.4 | B44: =($B$25+$B$26*$A44)*B$42 -> 207.668 | C44: =($B$25+$B$26*$A44)*C$42 -> 311.502 | D44: =($B$25+$B$26*$A44)*D$42 -> 415.336 | E44: =($B$25+$B$26*$A44)*E$42 -> 519.17 | F44: =($B$25+$B$26*$A44)*F$42 -> 623.004 | G44: =($B$25+$B$26*$A44)*G$42 -> 726.838 | H44: =($B$25+$B$26*$A44)*H$42 -> 830.672
A45: 0.5 | B45: =($B$25+$B$26*$A45)*B$42 -> 247.485 | C45: =($B$25+$B$26*$A45)*C$42 -> 371.2275 | D45: =($B$25+$B$26*$A45)*D$42 -> 494.97 | E45: =($B$25+$B$26*$A45)*E$42 -> 618.7125 | F45: =($B$25+$B$26*$A45)*F$42 -> 742.455 | G45: =($B$25+$B$26*$A45)*G$42 -> 866.1975 | H45: =($B$25+$B$26*$A45)*H$42 -> 989.94
A46: 0.6 | B46: =($B$25+$B$26*$A46)*B$42 -> 287.302 | C46: =($B$25+$B$26*$A46)*C$42 -> 430.953 | D46: =($B$25+$B$26*$A46)*D$42 -> 574.604 | E46: =($B$25+$B$26*$A46)*E$42 -> 718.255 | F46: =($B$25+$B$26*$A46)*F$42 -> 861.906 | G46: =($B$25+$B$26*$A46)*G$42 -> 1005.557 | H46: =($B$25+$B$26*$A46)*H$42 -> 1149.208
...

Sheet ResearchSummary
A1: (5) Cross-Check of Seven Sell-Side Reports (15 May to 24 June 2026)
A2: Covers Nomura (May 15, Jun 24), BofA (May 29), Goldman memory (May 31), Morgan Stanley (Jun 2), Goldman strategy (Jun 16) and SocGen (Jun 24). Documents supplied by the user.
A4: 1. Core Argument by House
A5: House | B5: Date | C5: Core argument | F5: Target multiple (Korean names) | G5: Micron-related comment
A6: Goldman memory | B6: 5/31 | C6: The durability of the upcycle is not in the price. DRAM supply falls short by 5.0%, 5.9% and 3.9% in 2026, 2027 and 2028, with the shortage persisting through 2028. | F6: SK hynix at 9.0x P/E (methodology switched from P/B to P/E), Samsung at 9.0x | G6: Target price of $484, from normalized FY26 EPS of $22 at 22x
A7: Nomura | B7: 5/15 | C7: AI demand has passed an inflection. Long-term agreements lower the risk premium and drive a re-rating, with 30% annual growth from 2027 to 2031. | F7: Samsung at 5.0x P/B (discount rate cut from 17% to 10%), SK hynix at 6.0x (21% to 12%) | G7: Samsung and SK hynix earnings will far exceed Micron’s (not rated)
A8: Nomura | B8: 6/24 | C8: Raised Q3 2026 DRAM by 24% and NAND by 25% quarter on quarter. HBM profitability converges to commodity levels in 2027. | F8: Samsung at 5.0x P/B (target KRW 670,000), SK hynix at 6.0x (target KRW 4,700,000) | G8: -
A9: BofA | B9: 5/29 | C9: Supply coverage stays above 110% through 2028 with no meaningful oversupply, and ASP volatility runs below historical levels. | F9: - | G9: Two-year-forward P/B of 3.28x sits far above the historical median of 1.54x - a valuation warning
A10: MS | B10: 6/2 | C10: Chipflation. The bottleneck moves from GPUs to memory as HBM cannibalizes commodity DRAM capacity, leaving PCs and smartphones 12-15% short. | F10: - | G10: Classified as a beneficiary with pricing power
A11: Goldman strategy | B11: 6/16 | C11: A post-modern cycle in a capital-intensive expansion phase, where EPS growth rather than valuation drives returns | F11: - | G11: Capex beneficiary theme
A12: SocGen | B12: 6/24 | C12: Korea carries cycle risk. Foreign outflows plus a surge in retail leveraged ETFs have amplified concentration risk. | F12: - | G12: The key risk for Korean investors is the semiconductor cycle turning
A14: 2. Applying Each House’s Methodology to Micron — Implied Price
A15: Warning: These mechanically apply target multiples set for Korean names to Micron. They are not the houses’ actual Micron views, with the exception of the Goldman US team.
A16: Methodology source | B16: Multiple applied | C16: Applied to | D16: Base | E16: Implied share price | F16: vs current price | G16: Character
A17: Nomura, SK hynix | B17: 6.0x P/B | C17: FY2027 consensus BPS | D17: =Consensus!E24 -> 259.02 | E17: =D17*6 -> 1554.12 | F17: =E17/Assumptions!$B$5-1 -> 0.7268 | G17: Most bullish
A18: Nomura, Samsung | B18: 5.0x P/B | C18: FY2027 consensus BPS | D18: =Consensus!E24 -> 259.02 | E18: =D18*5 -> 1295.1 | F18: =E18/Assumptions!$B$5-1 -> 0.439 | G18: Bull
A19: Goldman Korea team | B19: 9.0x P/E | C19: Average FY26-27 EPS | D19: =(Consensus!D18+Consensus!E18)/2 -> 113.895 | E19: =D19*9 -> 1025.055 | F19: =E19/Assumptions!$B$5-1 -> 0.13895 | G19: Bull
A20: Five-year average | B20: 1.95x P/B | C20: FY2028 consensus BPS | D20: =Consensus!F24 -> 437.94 | E20: =D20*1.95 -> 853.983 | F20: =E20/Assumptions!$B$5-1 -> -0.05113 | G20: Neutral
A21: BofA historical median | B21: 1.54x P/B | C21: FY2028 consensus BPS | D21: =Consensus!F24 -> 437.94 | E21: =D21*1.54 -> 674.4276 | F21: =E21/Assumptions!$B$5-1 -> -0.250636 | G21: Conservative
A22: Goldman US team (actual Micron view) | B22: 22.0x P/E | C22: Normalized EPS per Goldman | D22: =22 -> 22 | E22: =D22*22 -> 484 | F22: =E22/Assumptions!$B$5-1 -> -0.46222222 | G22: Most conservative
A23: Current share price | E23: =Assumptions!B5 -> 900
A24: ="Report methodologies span "&TEXT(MIN(E17:E22),"$#,##0")&" to "&TEXT(MAX(E17:E22),"$#,##0")&". The current price of "&TEXT(E23,"$#,##0")&" sits in the middle of that range." -> Report methodologies span $484 to $1,554. The current price of $900 sits in the middle of that range.
A26: 3. What Is Priced In and What Is Not
A27: Basis | B27: Item | C27: Report basis | F27: Check against the model | H27: Verdict
A28: Priced in | B28: The earnings explosion itself | C28: Consensus EPS of $73 in FY26 rising to $155 in FY27 | F28: Shares up 709% over 52 weeks. An FY27 P/E of 5.4x shows the earnings numbers are accepted. | H28: Priced in
A29: Priced in | B29: Shift to net cash and balance sheet strength | C29: Consensus FY28 net cash of $266B | F29: Debt to equity of 0.06 and a current ratio of 3.42, none of which shows up in the risk premium | H29: Priced in
A30: Not priced in | B30: Durability of earnings (the crux) | C30: Goldman: the durability of the upcycle is still not adequately valued by the market | F30: A P/E of 7.4x on average FY26-27 EPS, 18% below the Goldman target of 9x | H30: Not priced in
A31: Not priced in | B31: Lower risk premium from long-term agreements | C31: Nomura: prepayments, penalties and three-to-five-year commitments justify cutting the discount rate from 17% to 10% | F31: The model uses a 15% cost of equity on a 2.14 beta. No discount rate reduction is reflected. | H31: Not priced in
A32: Not priced in | B32: HBM ASP catch-up (2027) | C32: Goldman sees HBM ASP up 44-50% versus consensus at 34% | F32: Partly embedded in the 70.7% consensus FY27 net margin | H32: Partly
A33: Not priced in | B33: Structurally lower supply elasticity | C33: Goldman: capacity CAGR of 7-8% for 2026-30 versus 12% in 2017-18. BofA: most capex goes into cleanroom shells. | F33: The model does not treat supply explicitly and proxies it through the achievement rate lever | H33: Not priced in
A34: Not priced in | B34: Capacity to expand shareholder returns | C34: BofA: Micron dividend yield of 0.05% versus a historical median of 0.4% | F34: Payout is currently 1.2%. Normalizing the dividend would support the valuation. | H34: Not priced in
A35: Not priced in (bearish) | B35: Fallout from the 2027-28 capex surge | C35: Consensus capex of $27.7B in FY26 rising to $48.0B in FY28 and $55.5B in FY29 | F35: That build-out creates supply from FY2029, which the model does not capture beyond FY29 | H35: Not priced in
A36: Not priced in (bearish) | B36: China: CXMT and YMTC | C36: Nomura: 30% share domestically and 10% globally, with cleanroom expansion running faster than estimated | F36: A disruptor in commodity DRAM, though entry into leading-edge and HBM remains difficult | H36: Not priced in
A37: Not priced in (bearish) | B37: Power and datacenter construction delays | C37: Nomura calls this a meaningful bottleneck risk and suggests monitoring via satellite imagery | F37: Risk of demand being deferred. Consensus assumes on-time start-up. | H37: Not priced in
A38: Not priced in (bearish) | B38: Hyperscaler free cash flow margins at zero | C38: BofA: cloud FCF margins at zero in 2026-27, with capex at 95-100% of operating cash flow versus 35-50% historically | F38: If funding conditions deteriorate, capex is at risk of being cut | H38: Not priced in
A39: Not priced in (bearish) | B39: The sharp upward revision in BPS estimates themselves | C39: BofA on May 29: two-year-forward P/B of 3.28x. On the same basis today it is 1.91x. | F39: Warning: the share price rose while P/B fell, meaning BPS estimates were revised up roughly 2.6-3.2x | H39: Not priced in
A41: 4. Applying the Goldman Stress Scenario to Micron (cross-check)
A42: Goldman tested SK hynix under price declines of 20% in 2027 and 20% in 2028, and again at 30% and 30% for a cumulative fall of roughly 50%, and found operating margins holding in the mid-40s to mid-50s.
A43: Scenarios | B43: Assumed operating margin | C43: Adjusted FY28 revenue | D43: Estimated net income | E43: EPS | F43: At 9x P/E | G43: At 12x P/E
A44: Goldman scenario 1 (-20% / -20%) | B44: 0.55 | C44: =Consensus!F6*0.64 -> 182474.88 | D44: =C44*B44*0.85 -> 85307.006 | E44: =D44/Assumptions!$B$6 -> 75.492926 | F44: =E44*9 -> 679.43633 | G44: =E44*12 -> 905.91511
...

Sheet ChinaRisk
A1: (6) China Risk — CXMT Listing and Domestic Immersion DUV Production (2026-07-27)
A2: Warning: The seven research pieces above were all published between May 15 and Jun 24, before the Jul 27 events. Their China assessments are already stale.
A4: 1. What Happened (27 July 2026)
A5: CXMT lists on the Shanghai STAR Market | B5: Raised $8.6B, the largest Asian IPO of 2026. Up 466-472% on day one, market cap around $489B.
A6: Domestic immersion DUV enters production | B6: A Shanghai state-owned enterprise began producing immersion DUV tools. Roughly five units in 2026 and twenty in 2027.
A7: Delivery destinations | B7: SMIC, Hua Hong and CXMT - a memory maker is directly included
A8: Technical specification | B8: Rated for 28nm-class processes, with claims of reaching 7nm-class using multi-patterning
A9: Market reaction | B9: Over $1 trillion of market value erased. Micron -8%, SanDisk -15%, SK hynix ADR -8%.
A10: Regulatory status | B10: CXMT is designated a military company by the US Department of Defense. US legislators proposed additional immersion DUV restrictions in April.
A12: 2. CXMT Capacity — Conflict With the Goldman and Nomura Assumptions
A13: Item | B13: CXMT | C13: SK hynix | D13: Micron | E13: Samsung | F13: Note
A14: 2026 capacity additions (kwspm) | B14: 85 | C14: 60 | D14: 30 | E14: 15 | F14: CXMT alone equals 81% of the 105 kwspm added by the top three combined
A15: Total capacity at end-2026 (kwspm) | B15: 350 | C15: - | D15: 375 | E15: - | F15: Closes to within 25k of Micron
A16: Global DRAM share, 2027E | B16: 0.12 | C16: - | D16: - | E16: - | F16: CXMT target
A17: Global DRAM share, 2028E | B17: 0.17 | C17: - | D17: - | E17: - | F17: CXMT target
A19: Goldman (May 31) forecast undersupply through 2028 assuming top-three commodity DRAM capacity growth of 7-8% CAGR over 2026-30 and 15% supply growth. CXMT was not in that calculation.
A20: Nomura (Jun 24) judged there was no need for excessive concern at this stage, but the equipment bottleneck underpinning that view was shaken on Jul 27.
A22: 3. Micron Revenue Structure — Where the Exposure Sits
A23: Segment | B23: TTM revenue share | C23: TTM revenue ($m) | D23: CXMT threat level | E23: Rationale
A24: Commodity DRAM | B24: =MixPath!B26 -> 0.52981686 | C24: =B24*Assumptions!$B$19 -> 47828.687 | D24: High | E24: Over 98% of CXMT revenue is commodity DRAM, centred on DDR5 and LPDDR5X
A25: HBM | B25: =MixPath!B27 -> 0.23018314 | C25: =B25*Assumptions!$B$19 -> 20779.553 | D25: Low | E25: CXMT lists no HBM project in its IPO prospectus. HBM3E production is targeted for 2027, one to two generations behind.
A26: NAND | B26: =MixPath!B28 -> 0.24 | C26: =B26*Assumptions!$B$19 -> 21665.76 | D26: Medium | E26: YMTC is a separate threat, but CXMT is DRAM-only
A27: Note: DRAM is 76% of revenue (FY26 Q3) and HBM is over 30% of DRAM revenue, so commodity DRAM is roughly 53% of the total. More than half of Micron revenue sits in direct competition with CXMT.
A29: 4. Channel A — Sensitivity of Earnings to Impairment
A30: Commodity DRAM ASP decline scenario. Under a fixed-cost structure most of the revenue loss flows straight to profit (85% pass-through). [*] Revised 2026-07-31: the weight was changed from a fixed TTM 53% to the FY2028 value derived on MixPath.
A31: Commodity DRAM ASP decline | B31: FY28 revenue loss | C31: Adjusted net income | D31: Adjusted EPS | E31: At 6x P/E | F31: At 9x P/E | G31: At 12x P/E
A32: 0 | B32: =Consensus!F6*MixPath!$D$26*A32 -> 0 | C32: =Consensus!F15-B32*0.85 -> 189388 | D32: =C32/Assumptions!$B$6 -> 167.6 | E32: =D32*6 -> 1005.6 | F32: =D32*9 -> 1508.4 | G32: =D32*12 -> 2011.2
A33: 0.1 | B33: =Consensus!F6*MixPath!$D$26*A33 -> 16784.246 | C33: =Consensus!F15-B33*0.85 -> 175121.39 | D33: =C33/Assumptions!$B$6 -> 154.97468 | E33: =D33*6 -> 929.84809 | F33: =D33*9 -> 1394.7721 | G33: =D33*12 -> 1859.6962
A34: 0.2 | B34: =Consensus!F6*MixPath!$D$26*A34 -> 33568.492 | C34: =Consensus!F15-B34*0.85 -> 160854.78 | D34: =C34/Assumptions!$B$6 -> 142.34936 | E34: =D34*6 -> 854.09619 | F34: =D34*9 -> 1281.1443 | G34: =D34*12 -> 1708.1924
A35: 0.3 | B35: =Consensus!F6*MixPath!$D$26*A35 -> 50352.738 | C35: =Consensus!F15-B35*0.85 -> 146588.17 | D35: =C35/Assumptions!$B$6 -> 129.72405 | E35: =D35*6 -> 778.34428 | F35: =D35*9 -> 1167.5164 | G35: =D35*12 -> 1556.6886
A36: 0.4 | B36: =Consensus!F6*MixPath!$D$26*A36 -> 67136.984 | C36: =Consensus!F15-B36*0.85 -> 132321.56 | D36: =C36/Assumptions!$B$6 -> 117.09873 | E36: =D36*6 -> 702.59237 | F36: =D36*9 -> 1053.8886 | G36: =D36*12 -> 1405.1847
A37: 0.5 | B37: =Consensus!F6*MixPath!$D$26*A37 -> 83921.23 | C37: =Consensus!F15-B37*0.85 -> 118054.95 | D37: =C37/Assumptions!$B$6 -> 104.47341 | E37: =D37*6 -> 626.84047 | F37: =D37*9 -> 940.2607 | G37: =D37*12 -> 1253.6809
A38: Even with ASP down 30%, FY28 EPS is around $134, implying $1,200 at 9x. Through the earnings channel alone the damage is smaller than expected.
A39: Warning: The prior version applied the TTM commodity share of 53% to FY2028 revenue and overstated the CXMT threat. Mix shift makes the FY2028 commodity share lower - time is on Micron’s side.
A40: 5. Channel B — Impairment Through the Discount Rate [*] This Is the Real One
A41: Justified P/B = (ROE - g) / (COE - g). Holding FY2028 consensus BPS, a 30% sustainable ROE and 5% growth fixed, only the cost of equity varies.
A42: Scenarios | B42: COE | C42: Justified P/B | D42: Implied share price | E42: vs current price | F42: Interpretation
A43: Nomura argument (re-rating on long-term agreements) | B43: 0.1 | C43: =(Assumptions!$B$28-Assumptions!$B$29)/(B43-Assumptions!$B$29) -> 5 | D43: =C43*Consensus!F24 -> 2189.7 | E43: =D43/Assumptions!$B$5-1 -> 1.433 | F43: Argues for cutting the discount rate from 17% to 10%
